2023-12-15 17:06:13,833 INFO    StreamThr :314674 [internal.py:wandb_internal():86] W&B internal server running at pid: 314674, started at: 2023-12-15 17:06:13.832867
2023-12-15 17:06:13,834 DEBUG   HandlerThread:314674 [handler.py:handle_request():146] handle_request: status
2023-12-15 17:06:13,838 INFO    WriterThread:314674 [datastore.py:open_for_write():85] open: /media/cal314-1/9E044F59044F3415/Marcin/noisy_labels/wandb/run-20231215_170613-6xhul376/run-6xhul376.wandb
2023-12-15 17:06:13,839 DEBUG   SenderThread:314674 [sender.py:send():382] send: header
2023-12-15 17:06:13,845 DEBUG   SenderThread:314674 [sender.py:send():382] send: run
2023-12-15 17:06:14,272 ERROR   SenderThread:314674 [internal_api.py:execute():373] 403 response executing GraphQL.
2023-12-15 17:06:14,273 ERROR   SenderThread:314674 [internal_api.py:execute():374] {"errors":[{"message":"permission denied","path":["upsertBucket"],"extensions":{"code":"PERMISSION_ERROR"}}],"data":{"upsertBucket":null}}
2023-12-15 17:06:14,273 ERROR   SenderThread:314674 [sender.py:send_run():987] It appears that you do not have permission to access the requested resource. Please reach out to the project owner to grant you access. If you have the correct permissions, verify that there are no issues with your networking setup.(Error 403: Forbidden)
Traceback (most recent call last):
  File "/home/cal314-1/miniconda3/envs/marcin/lib/python3.11/site-packages/wandb/sdk/lib/retry.py", line 131, in __call__
    result = self._call_fn(*args, **kwargs)
             ^^^^^^^^^^^^^^^^^^^^^^^^^^^^^^
  File "/home/cal314-1/miniconda3/envs/marcin/lib/python3.11/site-packages/wandb/sdk/internal/internal_api.py", line 369, in execute
    return self.client.execute(*args, **kwargs)  # type: ignore
           ^^^^^^^^^^^^^^^^^^^^^^^^^^^^^^^^^^^^
  File "/home/cal314-1/miniconda3/envs/marcin/lib/python3.11/site-packages/wandb/vendor/gql-0.2.0/wandb_gql/client.py", line 52, in execute
    result = self._get_result(document, *args, **kwargs)
             ^^^^^^^^^^^^^^^^^^^^^^^^^^^^^^^^^^^^^^^^^^^
  File "/home/cal314-1/miniconda3/envs/marcin/lib/python3.11/site-packages/wandb/vendor/gql-0.2.0/wandb_gql/client.py", line 60, in _get_result
    return self.transport.execute(document, *args, **kwargs)
           ^^^^^^^^^^^^^^^^^^^^^^^^^^^^^^^^^^^^^^^^^^^^^^^^^
  File "/home/cal314-1/miniconda3/envs/marcin/lib/python3.11/site-packages/wandb/sdk/lib/gql_request.py", line 59, in execute
    request.raise_for_status()
  File "/home/cal314-1/miniconda3/envs/marcin/lib/python3.11/site-packages/requests/models.py", line 1021, in raise_for_status
    raise HTTPError(http_error_msg, response=self)
requests.exceptions.HTTPError: 403 Client Error: Forbidden for url: https://api.wandb.ai/graphql

During handling of the above exception, another exception occurred:

Traceback (most recent call last):
  File "/home/cal314-1/miniconda3/envs/marcin/lib/python3.11/site-packages/wandb/sdk/internal/sender.py", line 985, in send_run
    self._init_run(run, config_value_dict)
  File "/home/cal314-1/miniconda3/envs/marcin/lib/python3.11/site-packages/wandb/sdk/internal/sender.py", line 1027, in _init_run
    server_run, inserted, server_messages = self._api.upsert_run(
                                            ^^^^^^^^^^^^^^^^^^^^^
  File "/home/cal314-1/miniconda3/envs/marcin/lib/python3.11/site-packages/wandb/apis/normalize.py", line 73, in wrapper
    raise err
  File "/home/cal314-1/miniconda3/envs/marcin/lib/python3.11/site-packages/wandb/apis/normalize.py", line 41, in wrapper
    return func(*args, **kwargs)
           ^^^^^^^^^^^^^^^^^^^^^
  File "/home/cal314-1/miniconda3/envs/marcin/lib/python3.11/site-packages/wandb/sdk/internal/internal_api.py", line 2212, in upsert_run
    response = self.gql(
               ^^^^^^^^^
  File "/home/cal314-1/miniconda3/envs/marcin/lib/python3.11/site-packages/wandb/sdk/internal/internal_api.py", line 341, in gql
    ret = self._retry_gql(
          ^^^^^^^^^^^^^^^^
  File "/home/cal314-1/miniconda3/envs/marcin/lib/python3.11/site-packages/wandb/sdk/lib/retry.py", line 147, in __call__
    retry_timedelta_triggered = check_retry_fn(e)
                                ^^^^^^^^^^^^^^^^^
  File "/home/cal314-1/miniconda3/envs/marcin/lib/python3.11/site-packages/wandb/util.py", line 965, in check_retry_fn
    return fallback_retry_fn(e)
           ^^^^^^^^^^^^^^^^^^^^
  File "/home/cal314-1/miniconda3/envs/marcin/lib/python3.11/site-packages/wandb/util.py", line 907, in no_retry_auth
    raise CommError(
wandb.errors.CommError: It appears that you do not have permission to access the requested resource. Please reach out to the project owner to grant you access. If you have the correct permissions, verify that there are no issues with your networking setup.(Error 403: Forbidden)
2023-12-15 17:06:14,409 DEBUG   HandlerThread:314674 [handler.py:handle_request():146] handle_request: shutdown
2023-12-15 17:06:14,409 INFO    HandlerThread:314674 [handler.py:finish():866] shutting down handler
2023-12-15 17:06:14,845 INFO    WriterThread:314674 [datastore.py:close():294] close: /media/cal314-1/9E044F59044F3415/Marcin/noisy_labels/wandb/run-20231215_170613-6xhul376/run-6xhul376.wandb
2023-12-15 17:06:15,276 INFO    SenderThread:314674 [sender.py:finish():1548] shutting down sender
