
/media/cal314-1/9E044F59044F3415/Marcin/noisy_labels/Dataset/SegSperm/train
/media/cal314-1/9E044F59044F3415/Marcin/noisy_labels/Dataset/SegSperm/test_small
GPU dostÄ™pne: NVIDIA GeForce RTX 3090
Error: failed to send plot to http://127.0.0.1:63342
Traceback (most recent call last):
  File "/home/cal314-1/Downloads/pycharm-professional-2023.3.1/pycharm-2023.3.1/plugins/python/helpers/pycharm_display/datalore/display/display_.py", line 86, in _send_display_message
    urllib_request.urlopen(url, buffer)
  File "/home/cal314-1/miniconda3/envs/marcinv2/lib/python3.11/urllib/request.py", line 216, in urlopen
    return opener.open(url, data, timeout)
           ^^^^^^^^^^^^^^^^^^^^^^^^^^^^^^^
  File "/home/cal314-1/miniconda3/envs/marcinv2/lib/python3.11/urllib/request.py", line 525, in open
    response = meth(req, response)
               ^^^^^^^^^^^^^^^^^^^
  File "/home/cal314-1/miniconda3/envs/marcinv2/lib/python3.11/urllib/request.py", line 634, in http_response
    response = self.parent.error(
               ^^^^^^^^^^^^^^^^^^
  File "/home/cal314-1/miniconda3/envs/marcinv2/lib/python3.11/urllib/request.py", line 563, in error
    return self._call_chain(*args)
           ^^^^^^^^^^^^^^^^^^^^^^^
  File "/home/cal314-1/miniconda3/envs/marcinv2/lib/python3.11/urllib/request.py", line 496, in _call_chain
    result = func(*args)
             ^^^^^^^^^^^
  File "/home/cal314-1/miniconda3/envs/marcinv2/lib/python3.11/urllib/request.py", line 643, in http_error_default
    raise HTTPError(req.full_url, code, msg, hdrs, fp)
urllib.error.HTTPError: HTTP Error 429: Too Many Requests
During handling of the above exception, another exception occurred:
Traceback (most recent call last):
  File "/home/cal314-1/Downloads/pycharm-professional-2023.3.1/pycharm-2023.3.1/plugins/python/helpers/pycharm_display/datalore/display/display_.py", line 61, in try_empty_proxy
    urllib_request.urlopen(url, buffer)
  File "/home/cal314-1/miniconda3/envs/marcinv2/lib/python3.11/urllib/request.py", line 216, in urlopen
    return opener.open(url, data, timeout)
           ^^^^^^^^^^^^^^^^^^^^^^^^^^^^^^^
  File "/home/cal314-1/miniconda3/envs/marcinv2/lib/python3.11/urllib/request.py", line 525, in open
    response = meth(req, response)
               ^^^^^^^^^^^^^^^^^^^
  File "/home/cal314-1/miniconda3/envs/marcinv2/lib/python3.11/urllib/request.py", line 634, in http_response
    response = self.parent.error(
               ^^^^^^^^^^^^^^^^^^
  File "/home/cal314-1/miniconda3/envs/marcinv2/lib/python3.11/urllib/request.py", line 563, in error
    return self._call_chain(*args)
           ^^^^^^^^^^^^^^^^^^^^^^^
  File "/home/cal314-1/miniconda3/envs/marcinv2/lib/python3.11/urllib/request.py", line 496, in _call_chain
    result = func(*args)
             ^^^^^^^^^^^
  File "/home/cal314-1/miniconda3/envs/marcinv2/lib/python3.11/urllib/request.py", line 643, in http_error_default
    raise HTTPError(req.full_url, code, msg, hdrs, fp)
urllib.error.HTTPError: HTTP Error 429: Too Many Requests
Error: failed to send plot to http://127.0.0.1:63342
Traceback (most recent call last):
  File "/home/cal314-1/Downloads/pycharm-professional-2023.3.1/pycharm-2023.3.1/plugins/python/helpers/pycharm_display/datalore/display/display_.py", line 86, in _send_display_message
    urllib_request.urlopen(url, buffer)
  File "/home/cal314-1/miniconda3/envs/marcinv2/lib/python3.11/urllib/request.py", line 216, in urlopen
    return opener.open(url, data, timeout)
           ^^^^^^^^^^^^^^^^^^^^^^^^^^^^^^^
  File "/home/cal314-1/miniconda3/envs/marcinv2/lib/python3.11/urllib/request.py", line 525, in open
    response = meth(req, response)
               ^^^^^^^^^^^^^^^^^^^
  File "/home/cal314-1/miniconda3/envs/marcinv2/lib/python3.11/urllib/request.py", line 634, in http_response
    response = self.parent.error(
               ^^^^^^^^^^^^^^^^^^
  File "/home/cal314-1/miniconda3/envs/marcinv2/lib/python3.11/urllib/request.py", line 563, in error
    return self._call_chain(*args)
           ^^^^^^^^^^^^^^^^^^^^^^^
  File "/home/cal314-1/miniconda3/envs/marcinv2/lib/python3.11/urllib/request.py", line 496, in _call_chain
    result = func(*args)
             ^^^^^^^^^^^
  File "/home/cal314-1/miniconda3/envs/marcinv2/lib/python3.11/urllib/request.py", line 643, in http_error_default
    raise HTTPError(req.full_url, code, msg, hdrs, fp)
urllib.error.HTTPError: HTTP Error 429: Too Many Requests
During handling of the above exception, another exception occurred:
Traceback (most recent call last):
  File "/home/cal314-1/Downloads/pycharm-professional-2023.3.1/pycharm-2023.3.1/plugins/python/helpers/pycharm_display/datalore/display/display_.py", line 61, in try_empty_proxy
    urllib_request.urlopen(url, buffer)
  File "/home/cal314-1/miniconda3/envs/marcinv2/lib/python3.11/urllib/request.py", line 216, in urlopen
    return opener.open(url, data, timeout)
           ^^^^^^^^^^^^^^^^^^^^^^^^^^^^^^^
  File "/home/cal314-1/miniconda3/envs/marcinv2/lib/python3.11/urllib/request.py", line 525, in open
    response = meth(req, response)
               ^^^^^^^^^^^^^^^^^^^
  File "/home/cal314-1/miniconda3/envs/marcinv2/lib/python3.11/urllib/request.py", line 634, in http_response
    response = self.parent.error(
               ^^^^^^^^^^^^^^^^^^
  File "/home/cal314-1/miniconda3/envs/marcinv2/lib/python3.11/urllib/request.py", line 563, in error
    return self._call_chain(*args)
           ^^^^^^^^^^^^^^^^^^^^^^^
  File "/home/cal314-1/miniconda3/envs/marcinv2/lib/python3.11/urllib/request.py", line 496, in _call_chain
    result = func(*args)
             ^^^^^^^^^^^
  File "/home/cal314-1/miniconda3/envs/marcinv2/lib/python3.11/urllib/request.py", line 643, in http_error_default
    raise HTTPError(req.full_url, code, msg, hdrs, fp)
