2023-12-16 14:38:11,604 INFO    MainThread:26847 [wandb_setup.py:_flush():76] Current SDK version is 0.16.1
2023-12-16 14:38:11,604 INFO    MainThread:26847 [wandb_setup.py:_flush():76] Configure stats pid to 26847
2023-12-16 14:38:11,604 INFO    MainThread:26847 [wandb_setup.py:_flush():76] Loading settings from /home/nitro/.config/wandb/settings
2023-12-16 14:38:11,604 INFO    MainThread:26847 [wandb_setup.py:_flush():76] Loading settings from /home/nitro/Studia/Praca Dyplomowa/noisy_labels/wandb/settings
2023-12-16 14:38:11,604 INFO    MainThread:26847 [wandb_setup.py:_flush():76] Loading settings from environment variables: {'api_key': '***REDACTED***'}
2023-12-16 14:38:11,604 INFO    MainThread:26847 [wandb_setup.py:_flush():76] Applying setup settings: {'_disable_service': False}
2023-12-16 14:38:11,604 INFO    MainThread:26847 [wandb_setup.py:_flush():76] Inferring run settings from compute environment: {'program_relpath': 'Kod/train2.py', 'program_abspath': '/home/nitro/Studia/Praca Dyplomowa/noisy_labels/Kod/train2.py', 'program': '/home/nitro/Studia/Praca Dyplomowa/noisy_labels/Kod/train2.py'}
2023-12-16 14:38:11,604 INFO    MainThread:26847 [wandb_init.py:_log_setup():524] Logging user logs to /home/nitro/Studia/Praca Dyplomowa/noisy_labels/wandb/run-20231216_143811-1ibsgdiu/logs/debug.log
2023-12-16 14:38:11,604 INFO    MainThread:26847 [wandb_init.py:_log_setup():525] Logging internal logs to /home/nitro/Studia/Praca Dyplomowa/noisy_labels/wandb/run-20231216_143811-1ibsgdiu/logs/debug-internal.log
2023-12-16 14:38:11,604 INFO    MainThread:26847 [wandb_init.py:init():564] calling init triggers
2023-12-16 14:38:11,604 INFO    MainThread:26847 [wandb_init.py:init():571] wandb.init called with sweep_config: {}
config: {'epochs': 10, 'batch_size': 3, 'lr': 0.0001, 'annotator': 2, 'augmentation': False, 'loss': 'CrossEntropyLoss'}
2023-12-16 14:38:11,604 INFO    MainThread:26847 [wandb_init.py:init():614] starting backend
2023-12-16 14:38:11,604 INFO    MainThread:26847 [wandb_init.py:init():618] setting up manager
2023-12-16 14:38:11,606 INFO    MainThread:26847 [backend.py:_multiprocessing_setup():105] multiprocessing start_methods=fork,spawn,forkserver, using: spawn
2023-12-16 14:38:11,606 INFO    MainThread:26847 [wandb_init.py:init():624] backend started and connected
2023-12-16 14:38:11,610 INFO    MainThread:26847 [wandb_init.py:init():716] updated telemetry
2023-12-16 14:38:11,614 INFO    MainThread:26847 [wandb_init.py:init():749] communicating run to backend with 90.0 second timeout
2023-12-16 14:38:12,088 INFO    MainThread:26847 [wandb_run.py:_on_init():2254] communicating current version
2023-12-16 14:38:12,296 INFO    MainThread:26847 [wandb_run.py:_on_init():2263] got version response 
2023-12-16 14:38:12,296 INFO    MainThread:26847 [wandb_init.py:init():800] starting run threads in backend
2023-12-16 14:38:16,300 INFO    MainThread:26847 [wandb_run.py:_console_start():2233] atexit reg
2023-12-16 14:38:16,300 INFO    MainThread:26847 [wandb_run.py:_redirect():2088] redirect: wrap_raw
2023-12-16 14:38:16,300 INFO    MainThread:26847 [wandb_run.py:_redirect():2153] Wrapping output streams.
2023-12-16 14:38:16,301 INFO    MainThread:26847 [wandb_run.py:_redirect():2178] Redirects installed.
2023-12-16 14:38:16,301 INFO    MainThread:26847 [wandb_init.py:init():841] run started, returning control to user process
2023-12-16 14:39:09,418 INFO    MainThread:26847 [wandb_watch.py:watch():51] Watching
2023-12-16 14:40:30,345 INFO    MainThread:26847 [retry.py:__call__():172] Retry attempt failed:
Traceback (most recent call last):
  File "/home/nitro/miniconda3/envs/tf/lib/python3.10/site-packages/urllib3/connection.py", line 203, in _new_conn
    sock = connection.create_connection(
  File "/home/nitro/miniconda3/envs/tf/lib/python3.10/site-packages/urllib3/util/connection.py", line 60, in create_connection
    for res in socket.getaddrinfo(host, port, family, socket.SOCK_STREAM):
  File "/home/nitro/miniconda3/envs/tf/lib/python3.10/socket.py", line 955, in getaddrinfo
    for res in _socket.getaddrinfo(host, port, family, type, proto, flags):
socket.gaierror: [Errno -3] Temporary failure in name resolution

The above exception was the direct cause of the following exception:

Traceback (most recent call last):
  File "/home/nitro/miniconda3/envs/tf/lib/python3.10/site-packages/urllib3/connectionpool.py", line 790, in urlopen
    response = self._make_request(
  File "/home/nitro/miniconda3/envs/tf/lib/python3.10/site-packages/urllib3/connectionpool.py", line 491, in _make_request
    raise new_e
  File "/home/nitro/miniconda3/envs/tf/lib/python3.10/site-packages/urllib3/connectionpool.py", line 467, in _make_request
    self._validate_conn(conn)
  File "/home/nitro/miniconda3/envs/tf/lib/python3.10/site-packages/urllib3/connectionpool.py", line 1096, in _validate_conn
    conn.connect()
  File "/home/nitro/miniconda3/envs/tf/lib/python3.10/site-packages/urllib3/connection.py", line 611, in connect
    self.sock = sock = self._new_conn()
  File "/home/nitro/miniconda3/envs/tf/lib/python3.10/site-packages/urllib3/connection.py", line 210, in _new_conn
    raise NameResolutionError(self.host, self, e) from e
urllib3.exceptions.NameResolutionError: <urllib3.connection.HTTPSConnection object at 0x7f1d7aff2980>: Failed to resolve 'api.wandb.ai' ([Errno -3] Temporary failure in name resolution)

The above exception was the direct cause of the following exception:

Traceback (most recent call last):
  File "/home/nitro/miniconda3/envs/tf/lib/python3.10/site-packages/requests/adapters.py", line 486, in send
    resp = conn.urlopen(
  File "/home/nitro/miniconda3/envs/tf/lib/python3.10/site-packages/urllib3/connectionpool.py", line 844, in urlopen
    retries = retries.increment(
  File "/home/nitro/miniconda3/envs/tf/lib/python3.10/site-packages/urllib3/util/retry.py", line 515, in increment
    raise MaxRetryError(_pool, url, reason) from reason  # type: ignore[arg-type]
urllib3.exceptions.MaxRetryError: HTTPSConnectionPool(host='api.wandb.ai', port=443): Max retries exceeded with url: /graphql (Caused by NameResolutionError("<urllib3.connection.HTTPSConnection object at 0x7f1d7aff2980>: Failed to resolve 'api.wandb.ai' ([Errno -3] Temporary failure in name resolution)"))

During handling of the above exception, another exception occurred:

Traceback (most recent call last):
  File "/home/nitro/miniconda3/envs/tf/lib/python3.10/site-packages/wandb/sdk/lib/retry.py", line 131, in __call__
    result = self._call_fn(*args, **kwargs)
  File "/home/nitro/miniconda3/envs/tf/lib/python3.10/site-packages/wandb/sdk/internal/internal_api.py", line 369, in execute
    return self.client.execute(*args, **kwargs)  # type: ignore
  File "/home/nitro/miniconda3/envs/tf/lib/python3.10/site-packages/wandb/vendor/gql-0.2.0/wandb_gql/client.py", line 52, in execute
    result = self._get_result(document, *args, **kwargs)
  File "/home/nitro/miniconda3/envs/tf/lib/python3.10/site-packages/wandb/vendor/gql-0.2.0/wandb_gql/client.py", line 60, in _get_result
    return self.transport.execute(document, *args, **kwargs)
  File "/home/nitro/miniconda3/envs/tf/lib/python3.10/site-packages/wandb/sdk/lib/gql_request.py", line 58, in execute
    request = self.session.post(self.url, **post_args)
  File "/home/nitro/miniconda3/envs/tf/lib/python3.10/site-packages/requests/sessions.py", line 637, in post
    return self.request("POST", url, data=data, json=json, **kwargs)
  File "/home/nitro/miniconda3/envs/tf/lib/python3.10/site-packages/requests/sessions.py", line 589, in request
    resp = self.send(prep, **send_kwargs)
  File "/home/nitro/miniconda3/envs/tf/lib/python3.10/site-packages/requests/sessions.py", line 703, in send
    r = adapter.send(request, **kwargs)
  File "/home/nitro/miniconda3/envs/tf/lib/python3.10/site-packages/requests/adapters.py", line 519, in send
    raise ConnectionError(e, request=request)
requests.exceptions.ConnectionError: HTTPSConnectionPool(host='api.wandb.ai', port=443): Max retries exceeded with url: /graphql (Caused by NameResolutionError("<urllib3.connection.HTTPSConnection object at 0x7f1d7aff2980>: Failed to resolve 'api.wandb.ai' ([Errno -3] Temporary failure in name resolution)"))
