Traceback (most recent call last):
  File "/home/nitro/miniconda3/envs/tf/lib/python3.10/site-packages/wandb/sdk/wandb_config.py", line 162, in __getattr__
    return self.__getitem__(key)
  File "/home/nitro/miniconda3/envs/tf/lib/python3.10/site-packages/wandb/sdk/wandb_config.py", line 130, in __getitem__
    return self._items[key]
KeyError: 'augumentation'
The above exception was the direct cause of the following exception:
Traceback (most recent call last):
  File "/home/nitro/Studia/Praca Dyplomowa/noisy_labels/Kod/train2.py", line 144, in <module>
    name = print(f'Annotator:{config.annotator}, Augumentation:{config.augumentation} Epochs: {config.epochs},Batch_Size:{config.batch_size}, Start_lr:{config.lr}, Loss: {config.loss}, Timestamp: {timestamp}')
  File "/home/nitro/miniconda3/envs/tf/lib/python3.10/site-packages/wandb/sdk/wandb_config.py", line 164, in __getattr__
    raise AttributeError(
AttributeError: <class 'wandb.sdk.wandb_config.Config'> object has no attribute 'augumentation'